2023-02-23 11:29:45,298 - ERROR - __init__.py - _run_callback - 39 - Exception in callback functools.partial(<function HTTP1ServerConnection.start_serving.<locals>.<lambda> at 0x7f7e375a4510>, <Task finished coro=<HTTP1ServerConnection._server_request_loop() done, defined at /home/zi/session_book/lib64/python3.6/site-packages/tornado/http1connection.py:815> result=None>)
Traceback (most recent call last):
  File "/home/zi/session_book/base/__init__.py", line 35, in _run_callback
    self.add_future(ret, self)
  File "/home/zi/session_book/lib64/python3.6/site-packages/tornado/ioloop.py", line 691, in add_future
    assert is_future(future)
AssertionError
2023-02-23 12:28:11,034 - ERROR - __init__.py - _run_callback - 40 - Exception in callback functools.partial(<function HTTP1ServerConnection.start_serving.<locals>.<lambda> at 0x7fd309b75598>, <Task finished coro=<HTTP1ServerConnection._server_request_loop() done, defined at /home/zi/session_book/lib64/python3.6/site-packages/tornado/http1connection.py:815> result=None>)
Traceback (most recent call last):
  File "/home/zi/session_book/base/__init__.py", line 36, in _run_callback
    self.add_future(ret, self)
  File "/home/zi/session_book/lib64/python3.6/site-packages/tornado/ioloop.py", line 691, in add_future
    assert is_future(future)
AssertionError
2023-02-23 12:36:30,823 - ERROR - __init__.py - _run_callback - 40 - Exception in callback functools.partial(<function HTTP1ServerConnection.start_serving.<locals>.<lambda> at 0x7ff3b8002620>, <Task finished coro=<HTTP1ServerConnection._server_request_loop() done, defined at /home/zi/session_book/lib64/python3.6/site-packages/tornado/http1connection.py:815> result=None>)
Traceback (most recent call last):
  File "/home/zi/session_book/base/__init__.py", line 36, in _run_callback
    self.add_future(ret, self)
  File "/home/zi/session_book/lib64/python3.6/site-packages/tornado/ioloop.py", line 691, in add_future
    assert is_future(future)
AssertionError
2023-02-23 12:37:50,390 - ERROR - __init__.py - _run_callback - 40 - Exception in callback functools.partial(<function HTTP1ServerConnection.start_serving.<locals>.<lambda> at 0x7fc1cf7a8620>, <Task finished coro=<HTTP1ServerConnection._server_request_loop() done, defined at /home/zi/session_book/lib64/python3.6/site-packages/tornado/http1connection.py:815> result=None>)
Traceback (most recent call last):
  File "/home/zi/session_book/base/__init__.py", line 36, in _run_callback
    self.add_future(ret, self)
  File "/home/zi/session_book/lib64/python3.6/site-packages/tornado/ioloop.py", line 691, in add_future
    assert is_future(future)
AssertionError
2023-02-23 12:40:57,852 - ERROR - __init__.py - _run_callback - 40 - Exception in callback functools.partial(<function HTTP1ServerConnection.start_serving.<locals>.<lambda> at 0x7f86d0f15620>, <Task finished coro=<HTTP1ServerConnection._server_request_loop() done, defined at /home/zi/session_book/lib64/python3.6/site-packages/tornado/http1connection.py:815> result=None>)
Traceback (most recent call last):
  File "/home/zi/session_book/base/__init__.py", line 36, in _run_callback
    self.add_future(ret, self)
  File "/home/zi/session_book/lib64/python3.6/site-packages/tornado/ioloop.py", line 691, in add_future
    assert is_future(future)
AssertionError
2023-02-23 12:43:15,645 - ERROR - __init__.py - _run_callback - 40 - Exception in callback functools.partial(<function HTTP1ServerConnection.start_serving.<locals>.<lambda> at 0x7f8f2f0566a8>, <Task finished coro=<HTTP1ServerConnection._server_request_loop() done, defined at /home/zi/session_book/lib64/python3.6/site-packages/tornado/http1connection.py:815> result=None>)
Traceback (most recent call last):
  File "/home/zi/session_book/base/__init__.py", line 36, in _run_callback
    self.add_future(ret, self)
  File "/home/zi/session_book/lib64/python3.6/site-packages/tornado/ioloop.py", line 691, in add_future
    assert is_future(future)
AssertionError
2023-02-23 12:45:55,206 - ERROR - __init__.py - _run_callback - 40 - Exception in callback functools.partial(<function HTTP1ServerConnection.start_serving.<locals>.<lambda> at 0x7f2af722b620>, <Task finished coro=<HTTP1ServerConnection._server_request_loop() done, defined at /home/zi/session_book/lib64/python3.6/site-packages/tornado/http1connection.py:815> result=None>)
Traceback (most recent call last):
  File "/home/zi/session_book/base/__init__.py", line 36, in _run_callback
    self.add_future(ret, self)
  File "/home/zi/session_book/lib64/python3.6/site-packages/tornado/ioloop.py", line 691, in add_future
    assert is_future(future)
AssertionError
2023-02-23 12:47:31,325 - ERROR - __init__.py - _run_callback - 40 - Exception in callback functools.partial(<function HTTP1ServerConnection.start_serving.<locals>.<lambda> at 0x7f6f46dfd620>, <Task finished coro=<HTTP1ServerConnection._server_request_loop() done, defined at /home/zi/session_book/lib64/python3.6/site-packages/tornado/http1connection.py:815> result=None>)
Traceback (most recent call last):
  File "/home/zi/session_book/base/__init__.py", line 36, in _run_callback
    self.add_future(ret, self)
  File "/home/zi/session_book/lib64/python3.6/site-packages/tornado/ioloop.py", line 691, in add_future
    assert is_future(future)
AssertionError
2023-02-23 12:54:19,438 - ERROR - __init__.py - _run_callback - 40 - Exception in callback functools.partial(<function HTTP1ServerConnection.start_serving.<locals>.<lambda> at 0x7fbb8f7a8620>, <Task finished coro=<HTTP1ServerConnection._server_request_loop() done, defined at /home/zi/session_book/lib64/python3.6/site-packages/tornado/http1connection.py:815> result=None>)
Traceback (most recent call last):
  File "/home/zi/session_book/base/__init__.py", line 36, in _run_callback
    self.add_future(ret, self)
  File "/home/zi/session_book/lib64/python3.6/site-packages/tornado/ioloop.py", line 691, in add_future
    assert is_future(future)
AssertionError
2023-02-23 13:36:36,948 - ERROR - __init__.py - _run_callback - 40 - Exception in callback functools.partial(<function HTTP1ServerConnection.start_serving.<locals>.<lambda> at 0x7f17673496a8>, <Task finished coro=<HTTP1ServerConnection._server_request_loop() done, defined at /home/zi/session_book/lib64/python3.6/site-packages/tornado/http1connection.py:815> result=None>)
Traceback (most recent call last):
  File "/home/zi/session_book/base/__init__.py", line 36, in _run_callback
    self.add_future(ret, self)
  File "/home/zi/session_book/lib64/python3.6/site-packages/tornado/ioloop.py", line 691, in add_future
    assert is_future(future)
AssertionError
2023-02-23 13:37:33,629 - ERROR - __init__.py - _run_callback - 40 - Exception in callback functools.partial(<function HTTP1ServerConnection.start_serving.<locals>.<lambda> at 0x7f532e1f86a8>, <Task finished coro=<HTTP1ServerConnection._server_request_loop() done, defined at /home/zi/session_book/lib64/python3.6/site-packages/tornado/http1connection.py:815> result=None>)
Traceback (most recent call last):
  File "/home/zi/session_book/base/__init__.py", line 36, in _run_callback
    self.add_future(ret, self)
  File "/home/zi/session_book/lib64/python3.6/site-packages/tornado/ioloop.py", line 691, in add_future
    assert is_future(future)
AssertionError
2023-02-23 13:39:00,639 - ERROR - __init__.py - _run_callback - 40 - Exception in callback functools.partial(<function HTTP1ServerConnection.start_serving.<locals>.<lambda> at 0x7f92663166a8>, <Task finished coro=<HTTP1ServerConnection._server_request_loop() done, defined at /home/zi/session_book/lib64/python3.6/site-packages/tornado/http1connection.py:815> result=None>)
Traceback (most recent call last):
  File "/home/zi/session_book/base/__init__.py", line 36, in _run_callback
    self.add_future(ret, self)
  File "/home/zi/session_book/lib64/python3.6/site-packages/tornado/ioloop.py", line 691, in add_future
    assert is_future(future)
AssertionError
2023-02-23 13:39:30,199 - ERROR - __init__.py - _run_callback - 40 - Exception in callback functools.partial(<function HTTP1ServerConnection.start_serving.<locals>.<lambda> at 0x7fa9b470b6a8>, <Task finished coro=<HTTP1ServerConnection._server_request_loop() done, defined at /home/zi/session_book/lib64/python3.6/site-packages/tornado/http1connection.py:815> result=None>)
Traceback (most recent call last):
  File "/home/zi/session_book/base/__init__.py", line 36, in _run_callback
    self.add_future(ret, self)
  File "/home/zi/session_book/lib64/python3.6/site-packages/tornado/ioloop.py", line 691, in add_future
    assert is_future(future)
AssertionError
2023-02-23 13:41:03,525 - ERROR - __init__.py - _run_callback - 40 - Exception in callback functools.partial(<function HTTP1ServerConnection.start_serving.<locals>.<lambda> at 0x7f6da03286a8>, <Task finished coro=<HTTP1ServerConnection._server_request_loop() done, defined at /home/zi/session_book/lib64/python3.6/site-packages/tornado/http1connection.py:815> result=None>)
Traceback (most recent call last):
  File "/home/zi/session_book/base/__init__.py", line 36, in _run_callback
    self.add_future(ret, self)
  File "/home/zi/session_book/lib64/python3.6/site-packages/tornado/ioloop.py", line 691, in add_future
    assert is_future(future)
AssertionError
2023-02-23 13:41:37,683 - ERROR - __init__.py - _run_callback - 40 - Exception in callback functools.partial(<function HTTP1ServerConnection.start_serving.<locals>.<lambda> at 0x7fee2f82b6a8>, <Task finished coro=<HTTP1ServerConnection._server_request_loop() done, defined at /home/zi/session_book/lib64/python3.6/site-packages/tornado/http1connection.py:815> result=None>)
Traceback (most recent call last):
  File "/home/zi/session_book/base/__init__.py", line 36, in _run_callback
    self.add_future(ret, self)
  File "/home/zi/session_book/lib64/python3.6/site-packages/tornado/ioloop.py", line 691, in add_future
    assert is_future(future)
AssertionError
2023-02-23 14:14:37,316 - ERROR - __init__.py - _run_callback - 40 - Exception in callback functools.partial(<function HTTP1ServerConnection.start_serving.<locals>.<lambda> at 0x7f439508b840>, <Task finished coro=<HTTP1ServerConnection._server_request_loop() done, defined at /home/zi/session_book/lib64/python3.6/site-packages/tornado/http1connection.py:815> result=None>)
Traceback (most recent call last):
  File "/home/zi/session_book/base/__init__.py", line 36, in _run_callback
    self.add_future(ret, self)
  File "/home/zi/session_book/lib64/python3.6/site-packages/tornado/ioloop.py", line 691, in add_future
    assert is_future(future)
AssertionError
2023-02-23 14:15:00,018 - ERROR - __init__.py - _run_callback - 40 - Exception in callback functools.partial(<function HTTP1ServerConnection.start_serving.<locals>.<lambda> at 0x7f22dc5857b8>, <Task finished coro=<HTTP1ServerConnection._server_request_loop() done, defined at /home/zi/session_book/lib64/python3.6/site-packages/tornado/http1connection.py:815> result=None>)
Traceback (most recent call last):
  File "/home/zi/session_book/base/__init__.py", line 36, in _run_callback
    self.add_future(ret, self)
  File "/home/zi/session_book/lib64/python3.6/site-packages/tornado/ioloop.py", line 691, in add_future
    assert is_future(future)
AssertionError
2023-02-23 14:15:43,147 - ERROR - __init__.py - _run_callback - 40 - Exception in callback functools.partial(<function HTTP1ServerConnection.start_serving.<locals>.<lambda> at 0x7f22dc5857b8>, <Task finished coro=<HTTP1ServerConnection._server_request_loop() done, defined at /home/zi/session_book/lib64/python3.6/site-packages/tornado/http1connection.py:815> result=None>)
Traceback (most recent call last):
  File "/home/zi/session_book/base/__init__.py", line 36, in _run_callback
    self.add_future(ret, self)
  File "/home/zi/session_book/lib64/python3.6/site-packages/tornado/ioloop.py", line 691, in add_future
    assert is_future(future)
AssertionError
2023-02-23 14:15:50,340 - ERROR - __init__.py - _run_callback - 40 - Exception in callback functools.partial(<function HTTP1ServerConnection.start_serving.<locals>.<lambda> at 0x7f22dc5857b8>, <Task finished coro=<HTTP1ServerConnection._server_request_loop() done, defined at /home/zi/session_book/lib64/python3.6/site-packages/tornado/http1connection.py:815> result=None>)
Traceback (most recent call last):
  File "/home/zi/session_book/base/__init__.py", line 36, in _run_callback
    self.add_future(ret, self)
  File "/home/zi/session_book/lib64/python3.6/site-packages/tornado/ioloop.py", line 691, in add_future
    assert is_future(future)
AssertionError
2023-02-23 14:16:29,458 - ERROR - __init__.py - _run_callback - 40 - Exception in callback functools.partial(<function HTTP1ServerConnection.start_serving.<locals>.<lambda> at 0x7f82a284b7b8>, <Task finished coro=<HTTP1ServerConnection._server_request_loop() done, defined at /home/zi/session_book/lib64/python3.6/site-packages/tornado/http1connection.py:815> result=None>)
Traceback (most recent call last):
  File "/home/zi/session_book/base/__init__.py", line 36, in _run_callback
    self.add_future(ret, self)
  File "/home/zi/session_book/lib64/python3.6/site-packages/tornado/ioloop.py", line 691, in add_future
    assert is_future(future)
AssertionError
2023-02-23 14:16:59,058 - ERROR - __init__.py - _run_callback - 40 - Exception in callback functools.partial(<function HTTP1ServerConnection.start_serving.<locals>.<lambda> at 0x7f1db00df7b8>, <Task finished coro=<HTTP1ServerConnection._server_request_loop() done, defined at /home/zi/session_book/lib64/python3.6/site-packages/tornado/http1connection.py:815> result=None>)
Traceback (most recent call last):
  File "/home/zi/session_book/base/__init__.py", line 36, in _run_callback
    self.add_future(ret, self)
  File "/home/zi/session_book/lib64/python3.6/site-packages/tornado/ioloop.py", line 691, in add_future
    assert is_future(future)
AssertionError
2023-02-23 14:20:06,639 - ERROR - __init__.py - _run_callback - 40 - Exception in callback functools.partial(<function HTTP1ServerConnection.start_serving.<locals>.<lambda> at 0x7f6657d0e7b8>, <Task finished coro=<HTTP1ServerConnection._server_request_loop() done, defined at /home/zi/session_book/lib64/python3.6/site-packages/tornado/http1connection.py:815> result=None>)
Traceback (most recent call last):
  File "/home/zi/session_book/base/__init__.py", line 36, in _run_callback
    self.add_future(ret, self)
  File "/home/zi/session_book/lib64/python3.6/site-packages/tornado/ioloop.py", line 691, in add_future
    assert is_future(future)
AssertionError
2023-02-23 14:20:51,596 - ERROR - __init__.py - _run_callback - 40 - Exception in callback functools.partial(<function HTTP1ServerConnection.start_serving.<locals>.<lambda> at 0x7f0e71e697b8>, <Task finished coro=<HTTP1ServerConnection._server_request_loop() done, defined at /home/zi/session_book/lib64/python3.6/site-packages/tornado/http1connection.py:815> result=None>)
Traceback (most recent call last):
  File "/home/zi/session_book/base/__init__.py", line 36, in _run_callback
    self.add_future(ret, self)
  File "/home/zi/session_book/lib64/python3.6/site-packages/tornado/ioloop.py", line 691, in add_future
    assert is_future(future)
AssertionError
2023-02-23 14:21:50,251 - ERROR - __init__.py - _run_callback - 40 - Exception in callback functools.partial(<function HTTP1ServerConnection.start_serving.<locals>.<lambda> at 0x7f935b2647b8>, <Task finished coro=<HTTP1ServerConnection._server_request_loop() done, defined at /home/zi/session_book/lib64/python3.6/site-packages/tornado/http1connection.py:815> result=None>)
Traceback (most recent call last):
  File "/home/zi/session_book/base/__init__.py", line 36, in _run_callback
    self.add_future(ret, self)
  File "/home/zi/session_book/lib64/python3.6/site-packages/tornado/ioloop.py", line 691, in add_future
    assert is_future(future)
AssertionError
2023-02-23 14:26:07,355 - ERROR - __init__.py - _run_callback - 40 - Exception in callback functools.partial(<function HTTP1ServerConnection.start_serving.<locals>.<lambda> at 0x7f9f18039730>, <Task finished coro=<HTTP1ServerConnection._server_request_loop() done, defined at /home/zi/session_book/lib64/python3.6/site-packages/tornado/http1connection.py:815> result=None>)
Traceback (most recent call last):
  File "/home/zi/session_book/base/__init__.py", line 36, in _run_callback
    self.add_future(ret, self)
  File "/home/zi/session_book/lib64/python3.6/site-packages/tornado/ioloop.py", line 691, in add_future
    assert is_future(future)
AssertionError
2023-02-23 14:27:35,549 - ERROR - __init__.py - _run_callback - 40 - Exception in callback functools.partial(<function HTTP1ServerConnection.start_serving.<locals>.<lambda> at 0x7fe7306a67b8>, <Task finished coro=<HTTP1ServerConnection._server_request_loop() done, defined at /home/zi/session_book/lib64/python3.6/site-packages/tornado/http1connection.py:815> result=None>)
Traceback (most recent call last):
  File "/home/zi/session_book/base/__init__.py", line 36, in _run_callback
    self.add_future(ret, self)
  File "/home/zi/session_book/lib64/python3.6/site-packages/tornado/ioloop.py", line 691, in add_future
    assert is_future(future)
AssertionError
2023-02-23 14:30:23,016 - ERROR - __init__.py - _run_callback - 40 - Exception in callback functools.partial(<function HTTP1ServerConnection.start_serving.<locals>.<lambda> at 0x7fee93ac3730>, <Task finished coro=<HTTP1ServerConnection._server_request_loop() done, defined at /home/zi/session_book/lib64/python3.6/site-packages/tornado/http1connection.py:815> result=None>)
Traceback (most recent call last):
  File "/home/zi/session_book/base/__init__.py", line 36, in _run_callback
    self.add_future(ret, self)
  File "/home/zi/session_book/lib64/python3.6/site-packages/tornado/ioloop.py", line 691, in add_future
    assert is_future(future)
AssertionError
2023-02-23 14:31:50,072 - ERROR - __init__.py - _run_callback - 40 - Exception in callback functools.partial(<function HTTP1ServerConnection.start_serving.<locals>.<lambda> at 0x7f708096b730>, <Task finished coro=<HTTP1ServerConnection._server_request_loop() done, defined at /home/zi/session_book/lib64/python3.6/site-packages/tornado/http1connection.py:815> result=None>)
Traceback (most recent call last):
  File "/home/zi/session_book/base/__init__.py", line 36, in _run_callback
    self.add_future(ret, self)
  File "/home/zi/session_book/lib64/python3.6/site-packages/tornado/ioloop.py", line 691, in add_future
    assert is_future(future)
AssertionError
2023-02-23 14:32:38,807 - ERROR - __init__.py - _run_callback - 40 - Exception in callback functools.partial(<function HTTP1ServerConnection.start_serving.<locals>.<lambda> at 0x7f4aeb2d7730>, <Task finished coro=<HTTP1ServerConnection._server_request_loop() done, defined at /home/zi/session_book/lib64/python3.6/site-packages/tornado/http1connection.py:815> result=None>)
Traceback (most recent call last):
  File "/home/zi/session_book/base/__init__.py", line 36, in _run_callback
    self.add_future(ret, self)
  File "/home/zi/session_book/lib64/python3.6/site-packages/tornado/ioloop.py", line 691, in add_future
    assert is_future(future)
AssertionError
2023-02-23 14:34:42,519 - ERROR - __init__.py - _run_callback - 40 - Exception in callback functools.partial(<function HTTP1ServerConnection.start_serving.<locals>.<lambda> at 0x7fe525ab6730>, <Task finished coro=<HTTP1ServerConnection._server_request_loop() done, defined at /home/zi/session_book/lib64/python3.6/site-packages/tornado/http1connection.py:815> result=None>)
Traceback (most recent call last):
  File "/home/zi/session_book/base/__init__.py", line 36, in _run_callback
    self.add_future(ret, self)
  File "/home/zi/session_book/lib64/python3.6/site-packages/tornado/ioloop.py", line 691, in add_future
    assert is_future(future)
AssertionError
2023-02-23 14:35:38,612 - ERROR - __init__.py - _run_callback - 40 - Exception in callback functools.partial(<function HTTP1ServerConnection.start_serving.<locals>.<lambda> at 0x7f7b6b7a2730>, <Task finished coro=<HTTP1ServerConnection._server_request_loop() done, defined at /home/zi/session_book/lib64/python3.6/site-packages/tornado/http1connection.py:815> result=None>)
Traceback (most recent call last):
  File "/home/zi/session_book/base/__init__.py", line 36, in _run_callback
    self.add_future(ret, self)
  File "/home/zi/session_book/lib64/python3.6/site-packages/tornado/ioloop.py", line 691, in add_future
    assert is_future(future)
AssertionError
2023-02-23 14:36:26,945 - ERROR - __init__.py - _run_callback - 40 - Exception in callback functools.partial(<function HTTP1ServerConnection.start_serving.<locals>.<lambda> at 0x7fca88f2e730>, <Task finished coro=<HTTP1ServerConnection._server_request_loop() done, defined at /home/zi/session_book/lib64/python3.6/site-packages/tornado/http1connection.py:815> result=None>)
Traceback (most recent call last):
  File "/home/zi/session_book/base/__init__.py", line 36, in _run_callback
    self.add_future(ret, self)
  File "/home/zi/session_book/lib64/python3.6/site-packages/tornado/ioloop.py", line 691, in add_future
    assert is_future(future)
AssertionError
2023-02-23 14:37:54,150 - ERROR - __init__.py - _run_callback - 40 - Exception in callback functools.partial(<function HTTP1ServerConnection.start_serving.<locals>.<lambda> at 0x7f12c1fc2730>, <Task finished coro=<HTTP1ServerConnection._server_request_loop() done, defined at /home/zi/session_book/lib64/python3.6/site-packages/tornado/http1connection.py:815> result=None>)
Traceback (most recent call last):
  File "/home/zi/session_book/base/__init__.py", line 36, in _run_callback
    self.add_future(ret, self)
  File "/home/zi/session_book/lib64/python3.6/site-packages/tornado/ioloop.py", line 691, in add_future
    assert is_future(future)
AssertionError
2023-02-23 14:39:31,884 - ERROR - __init__.py - _run_callback - 40 - Exception in callback functools.partial(<function HTTP1ServerConnection.start_serving.<locals>.<lambda> at 0x7f532d31f730>, <Task finished coro=<HTTP1ServerConnection._server_request_loop() done, defined at /home/zi/session_book/lib64/python3.6/site-packages/tornado/http1connection.py:815> result=None>)
Traceback (most recent call last):
  File "/home/zi/session_book/base/__init__.py", line 36, in _run_callback
    self.add_future(ret, self)
  File "/home/zi/session_book/lib64/python3.6/site-packages/tornado/ioloop.py", line 691, in add_future
    assert is_future(future)
AssertionError
2023-02-23 14:40:43,967 - ERROR - __init__.py - _run_callback - 40 - Exception in callback functools.partial(<function HTTP1ServerConnection.start_serving.<locals>.<lambda> at 0x7f96c237f730>, <Task finished coro=<HTTP1ServerConnection._server_request_loop() done, defined at /home/zi/session_book/lib64/python3.6/site-packages/tornado/http1connection.py:815> result=None>)
Traceback (most recent call last):
  File "/home/zi/session_book/base/__init__.py", line 36, in _run_callback
    self.add_future(ret, self)
  File "/home/zi/session_book/lib64/python3.6/site-packages/tornado/ioloop.py", line 691, in add_future
    assert is_future(future)
AssertionError
2023-02-23 14:41:27,886 - ERROR - __init__.py - _run_callback - 40 - Exception in callback functools.partial(<function HTTP1ServerConnection.start_serving.<locals>.<lambda> at 0x7f78e2b10840>, <Task finished coro=<HTTP1ServerConnection._server_request_loop() done, defined at /home/zi/session_book/lib64/python3.6/site-packages/tornado/http1connection.py:815> result=None>)
Traceback (most recent call last):
  File "/home/zi/session_book/base/__init__.py", line 36, in _run_callback
    self.add_future(ret, self)
  File "/home/zi/session_book/lib64/python3.6/site-packages/tornado/ioloop.py", line 691, in add_future
    assert is_future(future)
AssertionError
2023-02-23 14:41:32,874 - ERROR - __init__.py - _run_callback - 40 - Exception in callback functools.partial(<function HTTP1ServerConnection.start_serving.<locals>.<lambda> at 0x7f78e2b10840>, <Task finished coro=<HTTP1ServerConnection._server_request_loop() done, defined at /home/zi/session_book/lib64/python3.6/site-packages/tornado/http1connection.py:815> result=None>)
Traceback (most recent call last):
  File "/home/zi/session_book/base/__init__.py", line 36, in _run_callback
    self.add_future(ret, self)
  File "/home/zi/session_book/lib64/python3.6/site-packages/tornado/ioloop.py", line 691, in add_future
    assert is_future(future)
AssertionError
2023-02-23 14:42:27,282 - ERROR - __init__.py - _run_callback - 40 - Exception in callback functools.partial(<function HTTP1ServerConnection.start_serving.<locals>.<lambda> at 0x7f25053f5840>, <Task finished coro=<HTTP1ServerConnection._server_request_loop() done, defined at /home/zi/session_book/lib64/python3.6/site-packages/tornado/http1connection.py:815> result=None>)
Traceback (most recent call last):
  File "/home/zi/session_book/base/__init__.py", line 36, in _run_callback
    self.add_future(ret, self)
  File "/home/zi/session_book/lib64/python3.6/site-packages/tornado/ioloop.py", line 691, in add_future
    assert is_future(future)
AssertionError
2023-02-23 14:45:18,207 - ERROR - __init__.py - _run_callback - 40 - Exception in callback functools.partial(<function HTTP1ServerConnection.start_serving.<locals>.<lambda> at 0x7f9a00acc840>, <Task finished coro=<HTTP1ServerConnection._server_request_loop() done, defined at /home/zi/session_book/lib64/python3.6/site-packages/tornado/http1connection.py:815> result=None>)
Traceback (most recent call last):
  File "/home/zi/session_book/base/__init__.py", line 36, in _run_callback
    self.add_future(ret, self)
  File "/home/zi/session_book/lib64/python3.6/site-packages/tornado/ioloop.py", line 691, in add_future
    assert is_future(future)
AssertionError
2023-02-23 14:45:28,596 - ERROR - __init__.py - _run_callback - 40 - Exception in callback functools.partial(<function HTTP1ServerConnection.start_serving.<locals>.<lambda> at 0x7f9a00acc840>, <Task finished coro=<HTTP1ServerConnection._server_request_loop() done, defined at /home/zi/session_book/lib64/python3.6/site-packages/tornado/http1connection.py:815> result=None>)
Traceback (most recent call last):
  File "/home/zi/session_book/base/__init__.py", line 36, in _run_callback
    self.add_future(ret, self)
  File "/home/zi/session_book/lib64/python3.6/site-packages/tornado/ioloop.py", line 691, in add_future
    assert is_future(future)
AssertionError
2023-02-23 14:46:47,363 - ERROR - __init__.py - _run_callback - 40 - Exception in callback functools.partial(<function HTTP1ServerConnection.start_serving.<locals>.<lambda> at 0x7f550aebb840>, <Task finished coro=<HTTP1ServerConnection._server_request_loop() done, defined at /home/zi/session_book/lib64/python3.6/site-packages/tornado/http1connection.py:815> result=None>)
Traceback (most recent call last):
  File "/home/zi/session_book/base/__init__.py", line 36, in _run_callback
    self.add_future(ret, self)
  File "/home/zi/session_book/lib64/python3.6/site-packages/tornado/ioloop.py", line 691, in add_future
    assert is_future(future)
AssertionError
2023-02-23 14:50:50,817 - ERROR - __init__.py - _run_callback - 40 - Exception in callback functools.partial(<function HTTP1ServerConnection.start_serving.<locals>.<lambda> at 0x7f6344d6f840>, <Task finished coro=<HTTP1ServerConnection._server_request_loop() done, defined at /home/zi/session_book/lib64/python3.6/site-packages/tornado/http1connection.py:815> result=None>)
Traceback (most recent call last):
  File "/home/zi/session_book/base/__init__.py", line 36, in _run_callback
    self.add_future(ret, self)
  File "/home/zi/session_book/lib64/python3.6/site-packages/tornado/ioloop.py", line 691, in add_future
    assert is_future(future)
AssertionError
2023-02-23 14:51:38,039 - ERROR - __init__.py - _run_callback - 40 - Exception in callback functools.partial(<function HTTP1ServerConnection.start_serving.<locals>.<lambda> at 0x7f3a4a8e1840>, <Task finished coro=<HTTP1ServerConnection._server_request_loop() done, defined at /home/zi/session_book/lib64/python3.6/site-packages/tornado/http1connection.py:815> result=None>)
Traceback (most recent call last):
  File "/home/zi/session_book/base/__init__.py", line 36, in _run_callback
    self.add_future(ret, self)
  File "/home/zi/session_book/lib64/python3.6/site-packages/tornado/ioloop.py", line 691, in add_future
    assert is_future(future)
AssertionError
2023-02-23 14:52:19,218 - ERROR - __init__.py - _run_callback - 40 - Exception in callback functools.partial(<function HTTP1ServerConnection.start_serving.<locals>.<lambda> at 0x7f8ce4c57840>, <Task finished coro=<HTTP1ServerConnection._server_request_loop() done, defined at /home/zi/session_book/lib64/python3.6/site-packages/tornado/http1connection.py:815> result=None>)
Traceback (most recent call last):
  File "/home/zi/session_book/base/__init__.py", line 36, in _run_callback
    self.add_future(ret, self)
  File "/home/zi/session_book/lib64/python3.6/site-packages/tornado/ioloop.py", line 691, in add_future
    assert is_future(future)
AssertionError
2023-02-23 14:53:08,192 - ERROR - __init__.py - _run_callback - 40 - Exception in callback functools.partial(<function HTTP1ServerConnection.start_serving.<locals>.<lambda> at 0x7f868ff57730>, <Task finished coro=<HTTP1ServerConnection._server_request_loop() done, defined at /home/zi/session_book/lib64/python3.6/site-packages/tornado/http1connection.py:815> result=None>)
Traceback (most recent call last):
  File "/home/zi/session_book/base/__init__.py", line 36, in _run_callback
    self.add_future(ret, self)
  File "/home/zi/session_book/lib64/python3.6/site-packages/tornado/ioloop.py", line 691, in add_future
    assert is_future(future)
AssertionError
2023-02-23 15:00:08,558 - ERROR - __init__.py - _run_callback - 40 - Exception in callback functools.partial(<function HTTP1ServerConnection.start_serving.<locals>.<lambda> at 0x7f53945a87b8>, <Task finished coro=<HTTP1ServerConnection._server_request_loop() done, defined at /home/zi/session_book/lib64/python3.6/site-packages/tornado/http1connection.py:815> result=None>)
Traceback (most recent call last):
  File "/home/zi/session_book/base/__init__.py", line 36, in _run_callback
    self.add_future(ret, self)
  File "/home/zi/session_book/lib64/python3.6/site-packages/tornado/ioloop.py", line 691, in add_future
    assert is_future(future)
AssertionError
2023-02-23 15:00:46,135 - ERROR - __init__.py - _run_callback - 40 - Exception in callback functools.partial(<function HTTP1ServerConnection.start_serving.<locals>.<lambda> at 0x7fd3267ac8c8>, <Task finished coro=<HTTP1ServerConnection._server_request_loop() done, defined at /home/zi/session_book/lib64/python3.6/site-packages/tornado/http1connection.py:815> result=None>)
Traceback (most recent call last):
  File "/home/zi/session_book/base/__init__.py", line 36, in _run_callback
    self.add_future(ret, self)
  File "/home/zi/session_book/lib64/python3.6/site-packages/tornado/ioloop.py", line 691, in add_future
    assert is_future(future)
AssertionError
2023-02-23 15:10:43,221 - ERROR - __init__.py - _run_callback - 40 - Exception in callback functools.partial(<function HTTP1ServerConnection.start_serving.<locals>.<lambda> at 0x7f527de778c8>, <Task finished coro=<HTTP1ServerConnection._server_request_loop() done, defined at /home/zi/session_book/lib64/python3.6/site-packages/tornado/http1connection.py:815> result=None>)
Traceback (most recent call last):
  File "/home/zi/session_book/base/__init__.py", line 36, in _run_callback
    self.add_future(ret, self)
  File "/home/zi/session_book/lib64/python3.6/site-packages/tornado/ioloop.py", line 691, in add_future
    assert is_future(future)
AssertionError
2023-02-23 15:12:06,598 - ERROR - __init__.py - _run_callback - 40 - Exception in callback functools.partial(<function HTTP1ServerConnection.start_serving.<locals>.<lambda> at 0x7fe5bf1a08c8>, <Task finished coro=<HTTP1ServerConnection._server_request_loop() done, defined at /home/zi/session_book/lib64/python3.6/site-packages/tornado/http1connection.py:815> result=None>)
Traceback (most recent call last):
  File "/home/zi/session_book/base/__init__.py", line 36, in _run_callback
    self.add_future(ret, self)
  File "/home/zi/session_book/lib64/python3.6/site-packages/tornado/ioloop.py", line 691, in add_future
    assert is_future(future)
AssertionError
2023-02-23 15:13:01,532 - ERROR - __init__.py - _run_callback - 40 - Exception in callback functools.partial(<function HTTP1ServerConnection.start_serving.<locals>.<lambda> at 0x7f6663c0e8c8>, <Task finished coro=<HTTP1ServerConnection._server_request_loop() done, defined at /home/zi/session_book/lib64/python3.6/site-packages/tornado/http1connection.py:815> result=None>)
Traceback (most recent call last):
  File "/home/zi/session_book/base/__init__.py", line 36, in _run_callback
    self.add_future(ret, self)
  File "/home/zi/session_book/lib64/python3.6/site-packages/tornado/ioloop.py", line 691, in add_future
    assert is_future(future)
AssertionError
2023-02-23 15:13:43,078 - ERROR - __init__.py - _run_callback - 40 - Exception in callback functools.partial(<function HTTP1ServerConnection.start_serving.<locals>.<lambda> at 0x7f957cc028c8>, <Task finished coro=<HTTP1ServerConnection._server_request_loop() done, defined at /home/zi/session_book/lib64/python3.6/site-packages/tornado/http1connection.py:815> result=None>)
Traceback (most recent call last):
  File "/home/zi/session_book/base/__init__.py", line 36, in _run_callback
    self.add_future(ret, self)
  File "/home/zi/session_book/lib64/python3.6/site-packages/tornado/ioloop.py", line 691, in add_future
    assert is_future(future)
AssertionError
2023-02-23 15:14:35,680 - ERROR - __init__.py - _run_callback - 40 - Exception in callback functools.partial(<function HTTP1ServerConnection.start_serving.<locals>.<lambda> at 0x7fd43b5598c8>, <Task finished coro=<HTTP1ServerConnection._server_request_loop() done, defined at /home/zi/session_book/lib64/python3.6/site-packages/tornado/http1connection.py:815> result=None>)
Traceback (most recent call last):
  File "/home/zi/session_book/base/__init__.py", line 36, in _run_callback
    self.add_future(ret, self)
  File "/home/zi/session_book/lib64/python3.6/site-packages/tornado/ioloop.py", line 691, in add_future
    assert is_future(future)
AssertionError
2023-02-23 15:15:56,356 - ERROR - __init__.py - _run_callback - 40 - Exception in callback functools.partial(<function HTTP1ServerConnection.start_serving.<locals>.<lambda> at 0x7f6a2ef698c8>, <Task finished coro=<HTTP1ServerConnection._server_request_loop() done, defined at /home/zi/session_book/lib64/python3.6/site-packages/tornado/http1connection.py:815> result=None>)
Traceback (most recent call last):
  File "/home/zi/session_book/base/__init__.py", line 36, in _run_callback
    self.add_future(ret, self)
  File "/home/zi/session_book/lib64/python3.6/site-packages/tornado/ioloop.py", line 691, in add_future
    assert is_future(future)
AssertionError
2023-02-23 15:17:05,387 - ERROR - __init__.py - _run_callback - 40 - Exception in callback functools.partial(<function HTTP1ServerConnection.start_serving.<locals>.<lambda> at 0x7f44f97e88c8>, <Task finished coro=<HTTP1ServerConnection._server_request_loop() done, defined at /home/zi/session_book/lib64/python3.6/site-packages/tornado/http1connection.py:815> result=None>)
Traceback (most recent call last):
  File "/home/zi/session_book/base/__init__.py", line 36, in _run_callback
    self.add_future(ret, self)
  File "/home/zi/session_book/lib64/python3.6/site-packages/tornado/ioloop.py", line 691, in add_future
    assert is_future(future)
AssertionError
2023-02-23 15:18:16,844 - ERROR - __init__.py - _run_callback - 40 - Exception in callback functools.partial(<function HTTP1ServerConnection.start_serving.<locals>.<lambda> at 0x7f888a4d68c8>, <Task finished coro=<HTTP1ServerConnection._server_request_loop() done, defined at /home/zi/session_book/lib64/python3.6/site-packages/tornado/http1connection.py:815> result=None>)
Traceback (most recent call last):
  File "/home/zi/session_book/base/__init__.py", line 36, in _run_callback
    self.add_future(ret, self)
  File "/home/zi/session_book/lib64/python3.6/site-packages/tornado/ioloop.py", line 691, in add_future
    assert is_future(future)
AssertionError
2023-02-23 15:21:35,128 - ERROR - __init__.py - _run_callback - 40 - Exception in callback functools.partial(<function HTTP1ServerConnection.start_serving.<locals>.<lambda> at 0x7f21b6408950>, <Task finished coro=<HTTP1ServerConnection._server_request_loop() done, defined at /home/zi/session_book/lib64/python3.6/site-packages/tornado/http1connection.py:815> result=None>)
Traceback (most recent call last):
  File "/home/zi/session_book/base/__init__.py", line 36, in _run_callback
    self.add_future(ret, self)
  File "/home/zi/session_book/lib64/python3.6/site-packages/tornado/ioloop.py", line 691, in add_future
    assert is_future(future)
AssertionError
2023-02-23 15:26:25,599 - ERROR - __init__.py - _run_callback - 40 - Exception in callback functools.partial(<function HTTP1ServerConnection.start_serving.<locals>.<lambda> at 0x7fbf8694f0d0>, <Task finished coro=<HTTP1ServerConnection._server_request_loop() done, defined at /home/zi/session_book/lib64/python3.6/site-packages/tornado/http1connection.py:815> result=None>)
Traceback (most recent call last):
  File "/home/zi/session_book/base/__init__.py", line 36, in _run_callback
    self.add_future(ret, self)
  File "/home/zi/session_book/lib64/python3.6/site-packages/tornado/ioloop.py", line 691, in add_future
    assert is_future(future)
AssertionError
2023-02-23 15:29:12,866 - ERROR - __init__.py - _run_callback - 40 - Exception in callback functools.partial(<function HTTP1ServerConnection.start_serving.<locals>.<lambda> at 0x7fdcd5d8f0d0>, <Task finished coro=<HTTP1ServerConnection._server_request_loop() done, defined at /home/zi/session_book/lib64/python3.6/site-packages/tornado/http1connection.py:815> result=None>)
Traceback (most recent call last):
  File "/home/zi/session_book/base/__init__.py", line 36, in _run_callback
    self.add_future(ret, self)
  File "/home/zi/session_book/lib64/python3.6/site-packages/tornado/ioloop.py", line 691, in add_future
    assert is_future(future)
AssertionError
2023-02-23 15:29:34,542 - ERROR - __init__.py - _run_callback - 40 - Exception in callback functools.partial(<function HTTP1ServerConnection.start_serving.<locals>.<lambda> at 0x7fbefee4d0d0>, <Task finished coro=<HTTP1ServerConnection._server_request_loop() done, defined at /home/zi/session_book/lib64/python3.6/site-packages/tornado/http1connection.py:815> result=None>)
Traceback (most recent call last):
  File "/home/zi/session_book/base/__init__.py", line 36, in _run_callback
    self.add_future(ret, self)
  File "/home/zi/session_book/lib64/python3.6/site-packages/tornado/ioloop.py", line 691, in add_future
    assert is_future(future)
AssertionError
2023-02-23 15:36:27,030 - ERROR - __init__.py - _run_callback - 40 - Exception in callback functools.partial(<function HTTP1ServerConnection.start_serving.<locals>.<lambda> at 0x7efd94054158>, <Task finished coro=<HTTP1ServerConnection._server_request_loop() done, defined at /home/zi/session_book/lib64/python3.6/site-packages/tornado/http1connection.py:815> result=None>)
Traceback (most recent call last):
  File "/home/zi/session_book/base/__init__.py", line 36, in _run_callback
    self.add_future(ret, self)
  File "/home/zi/session_book/lib64/python3.6/site-packages/tornado/ioloop.py", line 691, in add_future
    assert is_future(future)
AssertionError
2023-02-23 15:37:03,616 - ERROR - __init__.py - _run_callback - 40 - Exception in callback functools.partial(<function HTTP1ServerConnection.start_serving.<locals>.<lambda> at 0x7f089bc3b048>, <Task finished coro=<HTTP1ServerConnection._server_request_loop() done, defined at /home/zi/session_book/lib64/python3.6/site-packages/tornado/http1connection.py:815> result=None>)
Traceback (most recent call last):
  File "/home/zi/session_book/base/__init__.py", line 36, in _run_callback
    self.add_future(ret, self)
  File "/home/zi/session_book/lib64/python3.6/site-packages/tornado/ioloop.py", line 691, in add_future
    assert is_future(future)
AssertionError
2023-02-23 15:39:15,157 - ERROR - __init__.py - _run_callback - 40 - Exception in callback functools.partial(<function HTTP1ServerConnection.start_serving.<locals>.<lambda> at 0x7f581f114048>, <Task finished coro=<HTTP1ServerConnection._server_request_loop() done, defined at /home/zi/session_book/lib64/python3.6/site-packages/tornado/http1connection.py:815> result=None>)
Traceback (most recent call last):
  File "/home/zi/session_book/base/__init__.py", line 36, in _run_callback
    self.add_future(ret, self)
  File "/home/zi/session_book/lib64/python3.6/site-packages/tornado/ioloop.py", line 691, in add_future
    assert is_future(future)
AssertionError
2023-02-23 15:39:37,474 - ERROR - __init__.py - _run_callback - 40 - Exception in callback functools.partial(<function HTTP1ServerConnection.start_serving.<locals>.<lambda> at 0x7ff50e4fc048>, <Task finished coro=<HTTP1ServerConnection._server_request_loop() done, defined at /home/zi/session_book/lib64/python3.6/site-packages/tornado/http1connection.py:815> result=None>)
Traceback (most recent call last):
  File "/home/zi/session_book/base/__init__.py", line 36, in _run_callback
    self.add_future(ret, self)
  File "/home/zi/session_book/lib64/python3.6/site-packages/tornado/ioloop.py", line 691, in add_future
    assert is_future(future)
AssertionError
2023-02-23 15:39:51,970 - ERROR - __init__.py - _run_callback - 40 - Exception in callback functools.partial(<function HTTP1ServerConnection.start_serving.<locals>.<lambda> at 0x7ff50e4fc048>, <Task finished coro=<HTTP1ServerConnection._server_request_loop() done, defined at /home/zi/session_book/lib64/python3.6/site-packages/tornado/http1connection.py:815> result=None>)
Traceback (most recent call last):
  File "/home/zi/session_book/base/__init__.py", line 36, in _run_callback
    self.add_future(ret, self)
  File "/home/zi/session_book/lib64/python3.6/site-packages/tornado/ioloop.py", line 691, in add_future
    assert is_future(future)
AssertionError
2023-02-23 15:40:18,874 - ERROR - __init__.py - _run_callback - 40 - Exception in callback functools.partial(<function HTTP1ServerConnection.start_serving.<locals>.<lambda> at 0x7fdedc2bc048>, <Task finished coro=<HTTP1ServerConnection._server_request_loop() done, defined at /home/zi/session_book/lib64/python3.6/site-packages/tornado/http1connection.py:815> result=None>)
Traceback (most recent call last):
  File "/home/zi/session_book/base/__init__.py", line 36, in _run_callback
    self.add_future(ret, self)
  File "/home/zi/session_book/lib64/python3.6/site-packages/tornado/ioloop.py", line 691, in add_future
    assert is_future(future)
AssertionError
2023-02-23 15:41:02,738 - ERROR - __init__.py - _run_callback - 40 - Exception in callback functools.partial(<function HTTP1ServerConnection.start_serving.<locals>.<lambda> at 0x7f1c774f8048>, <Task finished coro=<HTTP1ServerConnection._server_request_loop() done, defined at /home/zi/session_book/lib64/python3.6/site-packages/tornado/http1connection.py:815> result=None>)
Traceback (most recent call last):
  File "/home/zi/session_book/base/__init__.py", line 36, in _run_callback
    self.add_future(ret, self)
  File "/home/zi/session_book/lib64/python3.6/site-packages/tornado/ioloop.py", line 691, in add_future
    assert is_future(future)
AssertionError
2023-02-23 15:41:39,342 - ERROR - __init__.py - _run_callback - 40 - Exception in callback functools.partial(<function HTTP1ServerConnection.start_serving.<locals>.<lambda> at 0x7fa8df75a048>, <Task finished coro=<HTTP1ServerConnection._server_request_loop() done, defined at /home/zi/session_book/lib64/python3.6/site-packages/tornado/http1connection.py:815> result=None>)
Traceback (most recent call last):
  File "/home/zi/session_book/base/__init__.py", line 36, in _run_callback
    self.add_future(ret, self)
  File "/home/zi/session_book/lib64/python3.6/site-packages/tornado/ioloop.py", line 691, in add_future
    assert is_future(future)
AssertionError
2023-02-23 15:41:58,216 - ERROR - __init__.py - _run_callback - 40 - Exception in callback functools.partial(<function HTTP1ServerConnection.start_serving.<locals>.<lambda> at 0x7fcf3c1e1048>, <Task finished coro=<HTTP1ServerConnection._server_request_loop() done, defined at /home/zi/session_book/lib64/python3.6/site-packages/tornado/http1connection.py:815> result=None>)
Traceback (most recent call last):
  File "/home/zi/session_book/base/__init__.py", line 36, in _run_callback
    self.add_future(ret, self)
  File "/home/zi/session_book/lib64/python3.6/site-packages/tornado/ioloop.py", line 691, in add_future
    assert is_future(future)
AssertionError
2023-02-23 15:42:19,516 - ERROR - __init__.py - _run_callback - 40 - Exception in callback functools.partial(<function HTTP1ServerConnection.start_serving.<locals>.<lambda> at 0x7fb730f17048>, <Task finished coro=<HTTP1ServerConnection._server_request_loop() done, defined at /home/zi/session_book/lib64/python3.6/site-packages/tornado/http1connection.py:815> result=None>)
Traceback (most recent call last):
  File "/home/zi/session_book/base/__init__.py", line 36, in _run_callback
    self.add_future(ret, self)
  File "/home/zi/session_book/lib64/python3.6/site-packages/tornado/ioloop.py", line 691, in add_future
    assert is_future(future)
AssertionError
2023-02-23 15:43:31,741 - ERROR - __init__.py - _run_callback - 40 - Exception in callback functools.partial(<function HTTP1ServerConnection.start_serving.<locals>.<lambda> at 0x7f653a5d3048>, <Task finished coro=<HTTP1ServerConnection._server_request_loop() done, defined at /home/zi/session_book/lib64/python3.6/site-packages/tornado/http1connection.py:815> result=None>)
Traceback (most recent call last):
  File "/home/zi/session_book/base/__init__.py", line 36, in _run_callback
    self.add_future(ret, self)
  File "/home/zi/session_book/lib64/python3.6/site-packages/tornado/ioloop.py", line 691, in add_future
    assert is_future(future)
AssertionError
2023-02-23 15:44:14,319 - ERROR - __init__.py - _run_callback - 40 - Exception in callback functools.partial(<function HTTP1ServerConnection.start_serving.<locals>.<lambda> at 0x7fdf461ca048>, <Task finished coro=<HTTP1ServerConnection._server_request_loop() done, defined at /home/zi/session_book/lib64/python3.6/site-packages/tornado/http1connection.py:815> result=None>)
Traceback (most recent call last):
  File "/home/zi/session_book/base/__init__.py", line 36, in _run_callback
    self.add_future(ret, self)
  File "/home/zi/session_book/lib64/python3.6/site-packages/tornado/ioloop.py", line 691, in add_future
    assert is_future(future)
AssertionError
2023-02-23 15:45:40,645 - ERROR - __init__.py - _run_callback - 40 - Exception in callback functools.partial(<function HTTP1ServerConnection.start_serving.<locals>.<lambda> at 0x7f34e6134268>, <Task finished coro=<HTTP1ServerConnection._server_request_loop() done, defined at /home/zi/session_book/lib64/python3.6/site-packages/tornado/http1connection.py:815> result=None>)
Traceback (most recent call last):
  File "/home/zi/session_book/base/__init__.py", line 36, in _run_callback
    self.add_future(ret, self._discard_future_result)
  File "/home/zi/session_book/lib64/python3.6/site-packages/tornado/ioloop.py", line 691, in add_future
    assert is_future(future)
AssertionError
2023-02-23 16:12:29,012 - ERROR - __init__.py - _run_callback - 40 - Exception in callback functools.partial(<function HTTP1ServerConnection.start_serving.<locals>.<lambda> at 0x7f62b01fb048>, <Task finished coro=<HTTP1ServerConnection._server_request_loop() done, defined at /home/zi/session_book/lib64/python3.6/site-packages/tornado/http1connection.py:815> result=None>)
Traceback (most recent call last):
  File "/home/zi/session_book/base/__init__.py", line 36, in _run_callback
    self.add_future(ret, self._discard_future_result)
  File "/home/zi/session_book/lib64/python3.6/site-packages/tornado/ioloop.py", line 691, in add_future
    assert is_future(future)
AssertionError
2023-02-23 16:13:36,402 - ERROR - __init__.py - _run_callback - 40 - Exception in callback functools.partial(<function HTTP1ServerConnection.start_serving.<locals>.<lambda> at 0x7f89bd6e80d0>, <Task finished coro=<HTTP1ServerConnection._server_request_loop() done, defined at /home/zi/session_book/lib64/python3.6/site-packages/tornado/http1connection.py:815> result=None>)
Traceback (most recent call last):
  File "/home/zi/session_book/base/__init__.py", line 36, in _run_callback
    self.add_future(ret, self._discard_future_result)
  File "/home/zi/session_book/lib64/python3.6/site-packages/tornado/ioloop.py", line 691, in add_future
    assert is_future(future)
AssertionError
2023-02-23 16:15:17,464 - ERROR - __init__.py - _run_callback - 40 - Exception in callback functools.partial(<function HTTP1ServerConnection.start_serving.<locals>.<lambda> at 0x7f055da520d0>, <Task finished coro=<HTTP1ServerConnection._server_request_loop() done, defined at /home/zi/session_book/lib64/python3.6/site-packages/tornado/http1connection.py:815> result=None>)
Traceback (most recent call last):
  File "/home/zi/session_book/base/__init__.py", line 36, in _run_callback
    self.add_future(ret, self._discard_future_result)
  File "/home/zi/session_book/lib64/python3.6/site-packages/tornado/ioloop.py", line 691, in add_future
    assert is_future(future)
AssertionError
2023-02-23 16:15:37,487 - ERROR - __init__.py - _run_callback - 40 - Exception in callback functools.partial(<function HTTP1ServerConnection.start_serving.<locals>.<lambda> at 0x7fa7b3f320d0>, <Task finished coro=<HTTP1ServerConnection._server_request_loop() done, defined at /home/zi/session_book/lib64/python3.6/site-packages/tornado/http1connection.py:815> result=None>)
Traceback (most recent call last):
  File "/home/zi/session_book/base/__init__.py", line 36, in _run_callback
    self.add_future(ret, self._discard_future_result)
  File "/home/zi/session_book/lib64/python3.6/site-packages/tornado/ioloop.py", line 691, in add_future
    assert is_future(future)
AssertionError
2023-02-23 16:16:05,701 - ERROR - __init__.py - _run_callback - 40 - Exception in callback functools.partial(<function HTTP1ServerConnection.start_serving.<locals>.<lambda> at 0x7fa7b3f320d0>, <Task finished coro=<HTTP1ServerConnection._server_request_loop() done, defined at /home/zi/session_book/lib64/python3.6/site-packages/tornado/http1connection.py:815> result=None>)
Traceback (most recent call last):
  File "/home/zi/session_book/base/__init__.py", line 36, in _run_callback
    self.add_future(ret, self._discard_future_result)
  File "/home/zi/session_book/lib64/python3.6/site-packages/tornado/ioloop.py", line 691, in add_future
    assert is_future(future)
AssertionError
2023-02-23 16:22:54,085 - ERROR - __init__.py - _run_callback - 40 - Exception in callback functools.partial(<function HTTP1ServerConnection.start_serving.<locals>.<lambda> at 0x7fce297870d0>, <Task finished coro=<HTTP1ServerConnection._server_request_loop() done, defined at /home/zi/session_book/lib64/python3.6/site-packages/tornado/http1connection.py:815> result=None>)
Traceback (most recent call last):
  File "/home/zi/session_book/base/__init__.py", line 36, in _run_callback
    self.add_future(ret, self._discard_future_result)
  File "/home/zi/session_book/lib64/python3.6/site-packages/tornado/ioloop.py", line 691, in add_future
    assert is_future(future)
AssertionError
2023-02-23 16:23:06,505 - ERROR - __init__.py - _run_callback - 40 - Exception in callback functools.partial(<function HTTP1ServerConnection.start_serving.<locals>.<lambda> at 0x7f4f918cc0d0>, <Task finished coro=<HTTP1ServerConnection._server_request_loop() done, defined at /home/zi/session_book/lib64/python3.6/site-packages/tornado/http1connection.py:815> result=None>)
Traceback (most recent call last):
  File "/home/zi/session_book/base/__init__.py", line 36, in _run_callback
    self.add_future(ret, self._discard_future_result)
  File "/home/zi/session_book/lib64/python3.6/site-packages/tornado/ioloop.py", line 691, in add_future
    assert is_future(future)
AssertionError
2023-02-23 16:26:20,911 - ERROR - __init__.py - _run_callback - 40 - Exception in callback functools.partial(<function HTTP1ServerConnection.start_serving.<locals>.<lambda> at 0x7f09b63aa158>, <Task finished coro=<HTTP1ServerConnection._server_request_loop() done, defined at /home/zi/session_book/lib64/python3.6/site-packages/tornado/http1connection.py:815> result=None>)
Traceback (most recent call last):
  File "/home/zi/session_book/base/__init__.py", line 36, in _run_callback
    self.add_future(ret, self._discard_future_result)
  File "/home/zi/session_book/lib64/python3.6/site-packages/tornado/ioloop.py", line 691, in add_future
    assert is_future(future)
AssertionError
2023-02-23 16:26:32,736 - ERROR - __init__.py - _run_callback - 40 - Exception in callback functools.partial(<function HTTP1ServerConnection.start_serving.<locals>.<lambda> at 0x7f4014fb9158>, <Task finished coro=<HTTP1ServerConnection._server_request_loop() done, defined at /home/zi/session_book/lib64/python3.6/site-packages/tornado/http1connection.py:815> result=None>)
Traceback (most recent call last):
  File "/home/zi/session_book/base/__init__.py", line 36, in _run_callback
    self.add_future(ret, self._discard_future_result)
  File "/home/zi/session_book/lib64/python3.6/site-packages/tornado/ioloop.py", line 691, in add_future
    assert is_future(future)
AssertionError
2023-02-23 16:27:01,642 - ERROR - __init__.py - _run_callback - 40 - Exception in callback functools.partial(<function HTTP1ServerConnection.start_serving.<locals>.<lambda> at 0x7f6436df2158>, <Task finished coro=<HTTP1ServerConnection._server_request_loop() done, defined at /home/zi/session_book/lib64/python3.6/site-packages/tornado/http1connection.py:815> result=None>)
Traceback (most recent call last):
  File "/home/zi/session_book/base/__init__.py", line 36, in _run_callback
    self.add_future(ret, self._discard_future_result)
  File "/home/zi/session_book/lib64/python3.6/site-packages/tornado/ioloop.py", line 691, in add_future
    assert is_future(future)
AssertionError
